[2025-05-26 19:07:53,705] [ERROR] api_logger: Неправильно передан статус. Должен быть "опубликовано"/"завершено"/"черновик", а на деле status = 'string'
[2025-05-26 19:08:20,815] [ERROR] api_logger: Неправильно передан статус. Должен быть "опубликовано"/"завершено"/"черновик", а на деле status = 'опубликовацно'
[2025-05-26 20:37:18,035] [ERROR] api_logger: Неправильно передан статус. Должен быть "опубликовано"/"завершено"/"черновик", а на деле status = 'опубликовацно'
[2025-05-26 20:38:02,045] [ERROR] api_logger: Неправильно передан статус. Должен быть "опубликовано"/"завершено"/"черновик", а на деле status = 'string'
[2025-05-26 20:38:18,464] [ERROR] api_logger: Неправильно передан статус. Должен быть "опубликовано"/"завершено"/"черновик", а на деле status = 'удален'
[2025-05-26 20:38:22,006] [ERROR] api_logger: Неправильно передан статус. Должен быть "опубликовано"/"завершено"/"черновик", а на деле status = 'удалено'
[2025-05-26 20:41:06,201] [ERROR] api_logger: Имя/Логин уже занят
[2025-05-26 20:57:19,859] [ERROR] api_logger: Неправильно передан статус. Должен быть "опубликовано"/"завершено"/"черновик", а на деле status = 'string'
[2025-05-30 14:43:07,121] [ERROR] api_logger: Имя/Логин уже занят
[2025-06-03 15:48:23,501] [ERROR] api_logger: Данный тип билета для этого мероприятия уже существует ticket_type = <TypeForm.VIP: 'Vip'>
[2025-06-03 21:32:50,839] [ERROR] api_logger: Данный тип билета для этого мероприяия уже существует ticket_type = <TypeForm.VIP: 'Vip'>
[2025-06-03 21:46:47,297] [ERROR] api_logger: Данный тип билета для этого мероприяия уже существует ticket_type = <TypeForm.VIP: 'Vip'>
[2025-06-03 21:47:03,764] [ERROR] api_logger: Данный тип билета для этого мероприяия уже существует ticket_type = <TypeForm.STANDARD: 'Standard'>
[2025-06-04 13:44:11,138] [ERROR] api_logger: Данный тип билета для этого мероприяия уже существует ticket_type = 'Vip'
[2025-06-04 15:27:44,911] [ERROR] api_logger: Данный тип билета для этого мероприяия уже существует ticket_type = 'Vip'
[2025-06-04 15:28:18,886] [ERROR] api_logger: Данный тип билета для этого мероприяия уже существует ticket_type = 'Vip'
[2025-06-04 15:45:25,556] [ERROR] api_logger: Внутренняя ошибка сервера. Проблемы с сейвом БД: (sqlite3.IntegrityError) NOT NULL constraint failed: events.category
[SQL: INSERT INTO events (creator_id, status, category, title, description, address) VALUES (?, ?, ?, ?, ?, ?) RETURNING id, datetime]
[parameters: (4, 'опубликовано', None, 'Конференция по Python', 'Ежегодная конференция для разработчиков', 'Ул. Штурманская, д. 30')]
(Background on this error at: https://sqlalche.me/e/20/gkpj)
Traceback (most recent call last):
  File "C:\Users\Admin\AppData\Local\Packages\PythonSoftwareFoundation.Python.3.11_qbz5n2kfra8p0\LocalCache\local-packages\Python311\site-packages\sqlalchemy\engine\base.py", line 1969, in _exec_single_context
    self.dialect.do_execute(
  File "C:\Users\Admin\AppData\Local\Packages\PythonSoftwareFoundation.Python.3.11_qbz5n2kfra8p0\LocalCache\local-packages\Python311\site-packages\sqlalchemy\engine\default.py", line 922, in do_execute
    cursor.execute(statement, parameters)
sqlite3.IntegrityError: NOT NULL constraint failed: events.category

The above exception was the direct cause of the following exception:

Traceback (most recent call last):
  File "C:\work\eventpass\backend\core_service\app\models\crud.py", line 216, in create_event
    db.commit()
  File "C:\Users\Admin\AppData\Local\Packages\PythonSoftwareFoundation.Python.3.11_qbz5n2kfra8p0\LocalCache\local-packages\Python311\site-packages\sqlalchemy\orm\session.py", line 1969, in commit
    trans.commit(_to_root=True)
  File "<string>", line 2, in commit
  File "C:\Users\Admin\AppData\Local\Packages\PythonSoftwareFoundation.Python.3.11_qbz5n2kfra8p0\LocalCache\local-packages\Python311\site-packages\sqlalchemy\orm\state_changes.py", line 139, in _go
    ret_value = fn(self, *arg, **kw)
                ^^^^^^^^^^^^^^^^^^^^
  File "C:\Users\Admin\AppData\Local\Packages\PythonSoftwareFoundation.Python.3.11_qbz5n2kfra8p0\LocalCache\local-packages\Python311\site-packages\sqlalchemy\orm\session.py", line 1256, in commit
    self._prepare_impl()
  File "<string>", line 2, in _prepare_impl
  File "C:\Users\Admin\AppData\Local\Packages\PythonSoftwareFoundation.Python.3.11_qbz5n2kfra8p0\LocalCache\local-packages\Python311\site-packages\sqlalchemy\orm\state_changes.py", line 139, in _go
    ret_value = fn(self, *arg, **kw)
                ^^^^^^^^^^^^^^^^^^^^
  File "C:\Users\Admin\AppData\Local\Packages\PythonSoftwareFoundation.Python.3.11_qbz5n2kfra8p0\LocalCache\local-packages\Python311\site-packages\sqlalchemy\orm\session.py", line 1231, in _prepare_impl
    self.session.flush()
  File "C:\Users\Admin\AppData\Local\Packages\PythonSoftwareFoundation.Python.3.11_qbz5n2kfra8p0\LocalCache\local-packages\Python311\site-packages\sqlalchemy\orm\session.py", line 4312, in flush
    self._flush(objects)
  File "C:\Users\Admin\AppData\Local\Packages\PythonSoftwareFoundation.Python.3.11_qbz5n2kfra8p0\LocalCache\local-packages\Python311\site-packages\sqlalchemy\orm\session.py", line 4447, in _flush
    with util.safe_reraise():
  File "C:\Users\Admin\AppData\Local\Packages\PythonSoftwareFoundation.Python.3.11_qbz5n2kfra8p0\LocalCache\local-packages\Python311\site-packages\sqlalchemy\util\langhelpers.py", line 146, in __exit__
    raise exc_value.with_traceback(exc_tb)
  File "C:\Users\Admin\AppData\Local\Packages\PythonSoftwareFoundation.Python.3.11_qbz5n2kfra8p0\LocalCache\local-packages\Python311\site-packages\sqlalchemy\orm\session.py", line 4408, in _flush
    flush_context.execute()
  File "C:\Users\Admin\AppData\Local\Packages\PythonSoftwareFoundation.Python.3.11_qbz5n2kfra8p0\LocalCache\local-packages\Python311\site-packages\sqlalchemy\orm\unitofwork.py", line 466, in execute
    rec.execute(self)
  File "C:\Users\Admin\AppData\Local\Packages\PythonSoftwareFoundation.Python.3.11_qbz5n2kfra8p0\LocalCache\local-packages\Python311\site-packages\sqlalchemy\orm\unitofwork.py", line 642, in execute
    util.preloaded.orm_persistence.save_obj(
  File "C:\Users\Admin\AppData\Local\Packages\PythonSoftwareFoundation.Python.3.11_qbz5n2kfra8p0\LocalCache\local-packages\Python311\site-packages\sqlalchemy\orm\persistence.py", line 93, in save_obj
    _emit_insert_statements(
  File "C:\Users\Admin\AppData\Local\Packages\PythonSoftwareFoundation.Python.3.11_qbz5n2kfra8p0\LocalCache\local-packages\Python311\site-packages\sqlalchemy\orm\persistence.py", line 1227, in _emit_insert_statements
    result = connection.execute(
             ^^^^^^^^^^^^^^^^^^^
  File "C:\Users\Admin\AppData\Local\Packages\PythonSoftwareFoundation.Python.3.11_qbz5n2kfra8p0\LocalCache\local-packages\Python311\site-packages\sqlalchemy\engine\base.py", line 1416, in execute
    return meth(
           ^^^^^
  File "C:\Users\Admin\AppData\Local\Packages\PythonSoftwareFoundation.Python.3.11_qbz5n2kfra8p0\LocalCache\local-packages\Python311\site-packages\sqlalchemy\sql\elements.py", line 517, in _execute_on_connection
    return connection._execute_clauseelement(
           ^^^^^^^^^^^^^^^^^^^^^^^^^^^^^^^^^^
  File "C:\Users\Admin\AppData\Local\Packages\PythonSoftwareFoundation.Python.3.11_qbz5n2kfra8p0\LocalCache\local-packages\Python311\site-packages\sqlalchemy\engine\base.py", line 1639, in _execute_clauseelement
    ret = self._execute_context(
          ^^^^^^^^^^^^^^^^^^^^^^
  File "C:\Users\Admin\AppData\Local\Packages\PythonSoftwareFoundation.Python.3.11_qbz5n2kfra8p0\LocalCache\local-packages\Python311\site-packages\sqlalchemy\engine\base.py", line 1848, in _execute_context
    return self._exec_single_context(
           ^^^^^^^^^^^^^^^^^^^^^^^^^^
  File "C:\Users\Admin\AppData\Local\Packages\PythonSoftwareFoundation.Python.3.11_qbz5n2kfra8p0\LocalCache\local-packages\Python311\site-packages\sqlalchemy\engine\base.py", line 1988, in _exec_single_context
    self._handle_dbapi_exception(
  File "C:\Users\Admin\AppData\Local\Packages\PythonSoftwareFoundation.Python.3.11_qbz5n2kfra8p0\LocalCache\local-packages\Python311\site-packages\sqlalchemy\engine\base.py", line 2344, in _handle_dbapi_exception
    raise sqlalchemy_exception.with_traceback(exc_info[2]) from e
  File "C:\Users\Admin\AppData\Local\Packages\PythonSoftwareFoundation.Python.3.11_qbz5n2kfra8p0\LocalCache\local-packages\Python311\site-packages\sqlalchemy\engine\base.py", line 1969, in _exec_single_context
    self.dialect.do_execute(
  File "C:\Users\Admin\AppData\Local\Packages\PythonSoftwareFoundation.Python.3.11_qbz5n2kfra8p0\LocalCache\local-packages\Python311\site-packages\sqlalchemy\engine\default.py", line 922, in do_execute
    cursor.execute(statement, parameters)
sqlalchemy.exc.IntegrityError: (sqlite3.IntegrityError) NOT NULL constraint failed: events.category
[SQL: INSERT INTO events (creator_id, status, category, title, description, address) VALUES (?, ?, ?, ?, ?, ?) RETURNING id, datetime]
[parameters: (4, 'опубликовано', None, 'Конференция по Python', 'Ежегодная конференция для разработчиков', 'Ул. Штурманская, д. 30')]
(Background on this error at: https://sqlalche.me/e/20/gkpj)
